Workbook

Sheet accum_quarterly_data
B1: Wii 国内 | C1: Wii 米大陸 | D1: Wii その他 | E1: Wii U 国内 | F1: Wii U 米大陸 | G1: Wii U その他 | H1: Switch 国内 | I1: Switch 米大陸 | J1: Switch 欧州 | K1: Switch その他
A2: 38869
A3: 38961
A4: 39052
A5: 39142
A6: 39234
A7: 39326
A8: 39417
A9: 39508
A10: 39600
A11: 39692
A12: 39783
A13: 39873
... A29: 41334
A30: 41426 | B30: 2 | C30: 10 | D30: 9 | E30: 9 | F30: 6 | G30: 1
A31: 41518 | B31: 4 | C31: 28 | D31: 15 | E31: 23 | F31: 23 | G31: 1
A32: 41609 | B32: 4 | C32: 63 | D32: 40 | E32: 83 | F32: 120 | G32: 48
A33: 41699 | B33: 4 | C33: 71 | D33: 48 | E33: 89 | F33: 129 | G33: 55
A34: 41791 | B34: 0 | C34: 4 | D34: 5 | E34: 6 | F34: 28 | G34: 17
A35: 41883 | B35: 0 | C35: 8 | D35: 9 | E35: 17 | F35: 63 | G35: 32
A36: 41974 | B36: 0 | C36: 15 | D36: 22 | E36: 49 | F36: 164 | G36: 90
A37: 42064 | B37: 0 | C37: 18 | D37: 27 | E37: 53 | F37: 185 | G37: 100
A38: 42156 | B38: - | C38: 0 | D38: 4 | E38: 15 | F38: 19 | G38: 13
A39: 42248 | B39: - | C39: 0 | D39: 8 | E39: 22 | F39: 55 | G39: 31
A40: 42339 | B40: - | C40: 0 | D40: 11 | E40: 75 | F40: 145 | G40: 87
A41: 42430 | B41: - | C41: 0 | D41: 11 | E41: 80 | F41: 154 | G41: 91
A42: 42522 | E42: 7 | F42: 9 | G42: 5
A43: 42614 | E43: 16 | F43: 22 | G43: 18
A44: 42705 | E44: 20 | F44: 29 | G44: 26
A45: 42795 | E45: 20 | F45: 29 | G45: 26 | H45: 60 | I45: 120 | K45: 94
A46: 42887 | H46: 52 | I46: 75 | K46: 69
A47: 42979 | H47: 135 | I47: 192 | K47: 162
A48: 43070 | H48: 312 | I48: 474 | K48: 426
A49: 43160 | H49: 378 | I49: 594 | K49: 533
A50: 43252 | H50: 50 | I50: 67 | K50: 70
A51: 43344 | H51: 114 | I51: 200 | K51: 193
A52: 43435 | H52: 336 | I52: 580 | K52: 533
A53: 43525 | H53: 385 | I53: 688 | K53: 623
A54: 43617 | H54: 53 | I54: 82 | K54: 50
A55: 43709 | H55: 177 | I55: 263 | K55: 177
...

Sheet quarterly_data
B1: Wii_jp_sales | C1: Wii_us_sales | D1: Wii_others_sales | E1: WiiU_jp_sales | F1: WiiU_us_sales | G1: WiiU_others_sales | H1: Switch_jp_sales | I1: Switch_us_sales | J1: Switch_eur_sales | K1: Switch_others_sales
A2: 39052 | B2: 114 | C2: 125 | D2: 80
A3: 39142 | B3: 86 | C3: 112 | D3: 67
A4: 39234 | B4: 95 | C4: 144 | D4: 104
A5: 39326 | B5: 72 | C5: 165 | D5: 154
A6: 39417 | B6: 132 | C6: 339 | D6: 226
A7: 39508 | B7: 92 | C7: 176 | D7: 164
A8: 39600 | B8: 53 | C8: 250 | D8: 215
A9: 39692 | B9: 48 | C9: 208 | D9: 237
A10: 39783 | B10: 89 | C10: 522 | D10: 432
A11: 39873 | B11: 16 | C11: 314 | D11: 213
A12: 39965 | B12: 21 | C12: 88 | D12: 114
A13: 40057 | B13: 51 | C13: 157 | D13: 145
... A25: 41153 | B25: 12 | C25: 20 | D25: 29
A26: 41244 | B26: 5 | C26: 144 | D26: 72 | E26: 83 | F26: 132 | G26: 90
A27: 41334 | B27: 2 | C27: 20 | D27: 23 | E27: 9 | F27: 19 | G27: 11
A28: 41426 | B28: =accum_quarterly_data!B30 -> 2 | C28: =accum_quarterly_data!C30 -> 10 | D28: =accum_quarterly_data!D30 -> 9 | E28: =accum_quarterly_data!E30 -> 9 | F28: =accum_quarterly_data!F30 -> 6 | G28: =accum_quarterly_data!G30 -> 1
A29: 41518 | B29: =accum_quarterly_data!B31-accum_quarterly_data!B30 -> 2 | C29: =accum_quarterly_data!C31-accum_quarterly_data!C30 -> 18 | D29: =accum_quarterly_data!D31-accum_quarterly_data!D30 -> 6 | E29: =accum_quarterly_data!E31-accum_quarterly_data!E30 -> 14 | F29: =accum_quarterly_data!F31-accum_quarterly_data!F30 -> 17 | G29: =accum_quarterly_data!G31-accum_quarterly_data!G30 -> 0
A30: 41609 | B30: =accum_quarterly_data!B32-accum_quarterly_data!B31 -> 0 | C30: =accum_quarterly_data!C32-accum_quarterly_data!C31 -> 35 | D30: =accum_quarterly_data!D32-accum_quarterly_data!D31 -> 25 | E30: =accum_quarterly_data!E32-accum_quarterly_data!E31 -> 60 | F30: =accum_quarterly_data!F32-accum_quarterly_data!F31 -> 97 | G30: =accum_quarterly_data!G32-accum_quarterly_data!G31 -> 47
A31: 41699 | B31: =accum_quarterly_data!B33-accum_quarterly_data!B32 -> 0 | C31: =accum_quarterly_data!C33-accum_quarterly_data!C32 -> 8 | D31: =accum_quarterly_data!D33-accum_quarterly_data!D32 -> 8 | E31: =accum_quarterly_data!E33-accum_quarterly_data!E32 -> 6 | F31: =accum_quarterly_data!F33-accum_quarterly_data!F32 -> 9 | G31: =accum_quarterly_data!G33-accum_quarterly_data!G32 -> 7
A32: 41791 | B32: =accum_quarterly_data!B34 -> 0 | C32: =accum_quarterly_data!C34 -> 4 | D32: =accum_quarterly_data!D34 -> 5 | E32: =accum_quarterly_data!E34 -> 6 | F32: =accum_quarterly_data!F34 -> 28 | G32: =accum_quarterly_data!G34 -> 17
A33: 41883 | B33: =accum_quarterly_data!B35-accum_quarterly_data!B34 -> 0 | C33: =accum_quarterly_data!C35-accum_quarterly_data!C34 -> 4 | D33: =accum_quarterly_data!D35-accum_quarterly_data!D34 -> 4 | E33: =accum_quarterly_data!E35-accum_quarterly_data!E34 -> 11 | F33: =accum_quarterly_data!F35-accum_quarterly_data!F34 -> 35 | G33: =accum_quarterly_data!G35-accum_quarterly_data!G34 -> 15
A34: 41974 | B34: =accum_quarterly_data!B36-accum_quarterly_data!B35 -> 0 | C34: =accum_quarterly_data!C36-accum_quarterly_data!C35 -> 7 | D34: =accum_quarterly_data!D36-accum_quarterly_data!D35 -> 13 | E34: =accum_quarterly_data!E36-accum_quarterly_data!E35 -> 32 | F34: =accum_quarterly_data!F36-accum_quarterly_data!F35 -> 101 | G34: =accum_quarterly_data!G36-accum_quarterly_data!G35 -> 58
A35: 42064 | B35: =accum_quarterly_data!B37-accum_quarterly_data!B36 -> 0 | C35: =accum_quarterly_data!C37-accum_quarterly_data!C36 -> 3 | D35: =accum_quarterly_data!D37-accum_quarterly_data!D36 -> 5 | E35: =accum_quarterly_data!E37-accum_quarterly_data!E36 -> 4 | F35: =accum_quarterly_data!F37-accum_quarterly_data!F36 -> 21 | G35: =accum_quarterly_data!G37-accum_quarterly_data!G36 -> 10
A36: 42156 | B36: =accum_quarterly_data!B38 -> - | C36: =accum_quarterly_data!C38 -> 0 | D36: =accum_quarterly_data!D38 -> 4 | E36: =accum_quarterly_data!E38 -> 15 | F36: =accum_quarterly_data!F38 -> 19 | G36: =accum_quarterly_data!G38 -> 13
A37: 42248 | B37: =accum_quarterly_data!B39 -> - | C37: =accum_quarterly_data!C39-accum_quarterly_data!C38 -> 0 | D37: =accum_quarterly_data!D39-accum_quarterly_data!D38 -> 4 | E37: =accum_quarterly_data!E39-accum_quarterly_data!E38 -> 7 | F37: =accum_quarterly_data!F39-accum_quarterly_data!F38 -> 36 | G37: =accum_quarterly_data!G39-accum_quarterly_data!G38 -> 18
A38: 42339 | B38: =accum_quarterly_data!B40 -> - | C38: =accum_quarterly_data!C40-accum_quarterly_data!C39 -> 0 | D38: =accum_quarterly_data!D40-accum_quarterly_data!D39 -> 3 | E38: =accum_quarterly_data!E40-accum_quarterly_data!E39 -> 53 | F38: =accum_quarterly_data!F40-accum_quarterly_data!F39 -> 90 | G38: =accum_quarterly_data!G40-accum_quarterly_data!G39 -> 56
A39: 42430 | B39: =accum_quarterly_data!B41 -> - | C39: =accum_quarterly_data!C41-accum_quarterly_data!C40 -> 0 | D39: =accum_quarterly_data!D41-accum_quarterly_data!D40 -> 0 | E39: =accum_quarterly_data!E41-accum_quarterly_data!E40 -> 5 | F39: =accum_quarterly_data!F41-accum_quarterly_data!F40 -> 9 | G39: =accum_quarterly_data!G41-accum_quarterly_data!G40 -> 4
A40: 42522 | E40: =accum_quarterly_data!E42 -> 7 | F40: =accum_quarterly_data!F42 -> 9 | G40: =accum_quarterly_data!G42 -> 5
A41: 42614 | E41: =accum_quarterly_data!E43-accum_quarterly_data!E42 -> 9 | F41: =accum_quarterly_data!F43-accum_quarterly_data!F42 -> 13 | G41: =accum_quarterly_data!G43-accum_quarterly_data!G42 -> 13
A42: 42705 | E42: =accum_quarterly_data!E44-accum_quarterly_data!E43 -> 4 | F42: =accum_quarterly_data!F44-accum_quarterly_data!F43 -> 7 | G42: =accum_quarterly_data!G44-accum_quarterly_data!G43 -> 8 | H42: =accum_quarterly_data!H44-accum_quarterly_data!H43 -> 0 | I42: =accum_quarterly_data!I44-accum_quarterly_data!I43 -> 0 | J42: =accum_quarterly_data!J44-accum_quarterly_data!J43 -> 0 | K42: =accum_quarterly_data!K44-accum_quarterly_data!K43 -> 0
A43: 42795 | E43: =accum_quarterly_data!E45-accum_quarterly_data!E44 -> 0 | F43: =accum_quarterly_data!F45-accum_quarterly_data!F44 -> 0 | G43: =accum_quarterly_data!G45-accum_quarterly_data!G44 -> 0 | H43: =accum_quarterly_data!H45-accum_quarterly_data!H44 -> 60 | I43: =accum_quarterly_data!I45-accum_quarterly_data!I44 -> 120 | J43: =accum_quarterly_data!J45-accum_quarterly_data!J44 -> 0 | K43: =accum_quarterly_data!K45-accum_quarterly_data!K44 -> 94
A44: 42887 | H44: =accum_quarterly_data!H46 -> 52 | I44: =accum_quarterly_data!I46 -> 75 | J44: =accum_quarterly_data!J46 -> 0 | K44: =accum_quarterly_data!K46 -> 69
A45: 42979 | H45: =accum_quarterly_data!H47-accum_quarterly_data!H46 -> 83 | I45: =accum_quarterly_data!I47-accum_quarterly_data!I46 -> 117 | J45: =accum_quarterly_data!J47-accum_quarterly_data!J46 -> 0 | K45: =accum_quarterly_data!K47-accum_quarterly_data!K46 -> 93
A46: 43070 | H46: =accum_quarterly_data!H48-accum_quarterly_data!H47 -> 177 | I46: =accum_quarterly_data!I48-accum_quarterly_data!I47 -> 282 | J46: =accum_quarterly_data!J48-accum_quarterly_data!J47 -> 0 | K46: =accum_quarterly_data!K48-accum_quarterly_data!K47 -> 264
A47: 43160 | H47: =accum_quarterly_data!H49-accum_quarterly_data!H48 -> 66 | I47: =accum_quarterly_data!I49-accum_quarterly_data!I48 -> 120 | J47: =accum_quarterly_data!J49-accum_quarterly_data!J48 -> 0 | K47: =accum_quarterly_data!K49-accum_quarterly_data!K48 -> 107
A48: 43252 | H48: =accum_quarterly_data!H50 -> 50 | I48: =accum_quarterly_data!I50 -> 67 | J48: =accum_quarterly_data!J50 -> 0 | K48: =accum_quarterly_data!K50 -> 70
A49: 43344 | H49: =accum_quarterly_data!H51-accum_quarterly_data!H50 -> 64 | I49: =accum_quarterly_data!I51-accum_quarterly_data!I50 -> 133 | J49: =accum_quarterly_data!J51-accum_quarterly_data!J50 -> 0 | K49: =accum_quarterly_data!K51-accum_quarterly_data!K50 -> 123
A50: 43435 | H50: =accum_quarterly_data!H52-accum_quarterly_data!H51 -> 222 | I50: =accum_quarterly_data!I52-accum_quarterly_data!I51 -> 380 | J50: =accum_quarterly_data!J52-accum_quarterly_data!J51 -> 0 | K50: =accum_quarterly_data!K52-accum_quarterly_data!K51 -> 340
A51: 43525 | H51: =accum_quarterly_data!H53-accum_quarterly_data!H52 -> 49 | I51: =accum_quarterly_data!I53-accum_quarterly_data!I52 -> 108 | J51: =accum_quarterly_data!J53-accum_quarterly_data!J52 -> 0 | K51: =accum_quarterly_data!K53-accum_quarterly_data!K52 -> 90
...
